<?xml version='1.0'?>
<robot name="drone" xmlns:xacro="http://www.ros.org/wiki/xacro">
  <xacro:include filename="$(find drone_basic_py)/urdf/materials.xacro" />

  <link name="drone/base_footprint"></link>
  <joint name="drone/base_footprint_joint" type="fixed">
    <origin xyz="0 0 0" rpy="0 0 0" />
    <parent link="drone/base_footprint"/>
    <child link="drone/base_link" />
  </joint>

  <link name='drone/base_link'>
    <pose>0 0 0 0 0 0</pose>
    <inertial>
      <mass value="1"/>
      <origin xyz="0.0 0 0" rpy=" 0 0 0"/>
      <inertia
          ixx="0.0120193" ixy="0" ixz="0"
          iyy="0.023615" iyz="0"
          izz="0.0120193"
      />
    </inertial>

    <collision name='collision'>
      <origin xyz="0 0 0" rpy=" 0 0 0"/> 
      <geometry>
        <box size=".4 .4 .1"/>
      </geometry>
    </collision>

    <visual name='base_link_visual'>
      <origin xyz="0 0 0" rpy=" 0 0 0"/>
      <geometry>
        <mesh filename = "package://drone_basic_py/meshes/drone_model_basic.dae"/>
      </geometry>
      <material name="orange"/>
    </visual>
  </link>

<!-- Rotors and their joints -->
  <link name='drone/rotor_0'>
      <inertial>
        <mass value="0.005"/>
        <origin xyz="0 0 0" rpy=" 0 0 0"/>
        <inertia
            ixx="9.75e-07" ixy="0" ixz="0"
            iyy="4.17041e-05" iyz="0"
            izz="4.26041e-05"
        />
      </inertial>

      <collision name='rotor_0_collision'>
        <geometry>
        <cylinder length="0.005" radius="0.1"/>
        </geometry>
      </collision>

      <visual name='rotor_0_visual'>
        <origin xyz="0 0 0" rpy=" 0 0 0"/>
        <geometry>
          <mesh filename = "package://drone_basic_py/meshes/propeller_ccw.dae" scale="0.08 0.08 0.08"/>
        </geometry>
        <material name="blue"/>
      </visual>
    </link>

  <joint name="drone/rotor_0_joint" type="continuous">
    <parent link="drone/base_link"/>
    <child link="drone/rotor_0"/>
    <origin xyz="0.1 -0.1 0.023" rpy="0 0 0"/>
    <axis xyz="0 0 1" rpy="0 0 0"/>
    <dynamics damping="0.0" friction="0.0"/>
  </joint>

  <link name='drone/rotor_1'>
      <inertial>
        <mass value="0.005"/>
        <origin xyz="0 0 0" rpy="0 0 0"/>
        <inertia
            ixx="9.75e-07" ixy="0" ixz="0"
            iyy="4.17041e-05" iyz="0"
            izz="4.26041e-05"
        />
      </inertial>

      <collision name='rotor_1_collision'>
        <geometry>
        <cylinder length="0.005" radius="0.1"/>
        </geometry>
      </collision>

      <visual name='rotor_1_visual'>
        <origin xyz="0 0 0" rpy=" 0 0 0"/>
        <geometry>
          <mesh filename = "package://drone_basic_py/meshes/propeller_ccw.dae" scale="0.08 0.08 0.08"/>
        </geometry>
        <material name="red"/>
      </visual>
    </link>

  <joint name="drone/rotor_1_joint" type="continuous">
    <parent link="drone/base_link"/>
    <child link="drone/rotor_1"/>
    <origin xyz="-0.1 0.1 0.023" rpy="0 0 0"/>
    <axis xyz="0 0 1" rpy="0 0 0"/>
    <dynamics damping="0.0" friction="0.0"/>
  </joint>

  <link name='drone/rotor_2'>
      <inertial>
        <mass value="0.005"/>
        <origin xyz="0 0 0" rpy=" 0 0 0"/>
        <inertia
            ixx="9.75e-07" ixy="0" ixz="0"
            iyy="4.17041e-05" iyz="0"
            izz="4.26041e-05"
        />
      </inertial>

      <collision name='rotor_2_collision'>
        <geometry>
        <cylinder length="0.005" radius="0.1"/>
        </geometry>
      </collision>

      <visual name='rotor_2_visual'>
        <origin xyz="0 0 0" rpy="0 0 0"/>
        <geometry>
          <mesh filename = "package://drone_basic_py/meshes/propeller_cw.dae" scale="0.08 0.08 0.08"/>
        </geometry>
        <material name="blue"/>
      </visual>
    </link>

  <joint name="drone/rotor_2_joint" type="continuous">
    <parent link="drone/base_link"/>
    <child link="drone/rotor_2"/>
    <origin xyz="0.1 0.1 0.023" rpy="0 0 0"/>
    <axis xyz="0 0 1" rpy="0 0 0"/>
    <dynamics damping="0.0" friction="0.0"/>
  </joint>

  <link name='drone/rotor_3'>
      <inertial>
        <mass value="0.005"/>
        <origin xyz="0 0 0" rpy=" 0 0 0"/>
        <inertia
            ixx="9.75e-07" ixy="0" ixz="0"
            iyy="4.17041e-05" iyz="0"
            izz="4.26041e-05"
        />
      </inertial>

      <collision name='rotor_3_collision'>
        <geometry>
        <cylinder length="0.005" radius="0.1"/>
        </geometry>
      </collision>

      <visual name='rotor_3_visual'>
        <origin xyz="0 0 0" rpy="0 0 0"/>
        <geometry>
          <mesh filename = "package://drone_basic_py/meshes/propeller_cw.dae" scale="0.08 0.08 0.08"/>
        </geometry>
        <material name="red"/>
      </visual>
    </link>

  <joint name="drone/rotor_3_joint" type="continuous">
    <parent link="drone/base_link"/>
    <child link="drone/rotor_3"/>
    <origin xyz="-0.1 -0.1 0.023" rpy="0 0 0"/>
    <axis xyz="0 0 1" rpy="0 0 0"/>
    <dynamics damping="0.0" friction="0.0"/>
  </joint>

<!-- Camera and its joint -->
  <joint type="fixed" name="camera_joint">
    <origin xyz="0.2 0 0.0" rpy="0 0 0"/>
    <child link="camera_link"/>
    <parent link="drone/base_link"/>
    <axis xyz="0 1 0" />
  </joint>

  <link name='camera_link'>
    <pose>0 0 0 0 0 0</pose>
    <inertial>
      <mass value="0.0"/>
      <origin xyz="0 0 0" rpy="0 0 0"/>
      <inertia
          ixx="1e-6" ixy="0" ixz="0"
          iyy="1e-6" iyz="0"
          izz="1e-6"
      />
    </inertial>

    <collision name='collision'>
      <origin xyz="0 0 0" rpy="0 0 0"/> 
      <geometry>
        <box size=".03 .03 .03"/>
      </geometry>
    </collision>

    <visual name='camera_link_visual'>
      <origin xyz="0 0 0" rpy="0 0 0"/>
      <geometry>
        <box size=".03 .03 .03"/>
      </geometry>
    </visual>
  </link>

  <gazebo reference="camera_link">
    <material>Gazebo/Red</material>
  </gazebo>

  <joint type="fixed" name="camera_optical_joint">
    <origin xyz="0 0 0" rpy="-1.5707 0 -1.5707"/>
    <child link="camera_link_optical"/>
    <parent link="camera_link"/>
  </joint>

  <link name="camera_link_optical">
  </link>




  <xacro:include filename="$(find drone_basic_py)/urdf/drone_custom.gazebo" />
</robot>